{"uuid": "a9b4c0c5-70ff-4fc6-b28b-d3c0876cbb15", "children": ["f72cf2a1-3eba-4644-a517-d5130dbe1a90"], "befores": [{"name": "Фикстура создания и удаления задачи", "status": "failed", "statusDetails": {"message": "AssertionError: Ошибка при создании задачи\nassert 404 == 200\n +  where 404 = <Response [404]>.status_code\n", "trace": "  File \"/Users/iliakarpenko/Dev/test_exam/venv/lib/python3.13/site-packages/pluggy/_callers.py\", line 167, in _multicall\n    teardown.throw(outcome._exception)\n    ~~~~~~~~~~~~~~^^^^^^^^^^^^^^^^^^^^\n  File \"/Users/iliakarpenko/Dev/test_exam/venv/lib/python3.13/site-packages/_pytest/setuponly.py\", line 36, in pytest_fixture_setup\n    return (yield)\n            ^^^^^\n  File \"/Users/iliakarpenko/Dev/test_exam/venv/lib/python3.13/site-packages/pluggy/_callers.py\", line 103, in _multicall\n    res = hook_impl.function(*args)\n  File \"/Users/iliakarpenko/Dev/test_exam/venv/lib/python3.13/site-packages/_pytest/fixtures.py\", line 1140, in pytest_fixture_setup\n    result = call_fixture_func(fixturefunc, request, kwargs)\n  File \"/Users/iliakarpenko/Dev/test_exam/venv/lib/python3.13/site-packages/_pytest/fixtures.py\", line 891, in call_fixture_func\n    fixture_result = next(generator)\n  File \"/Users/iliakarpenko/Dev/test_exam/tests/conftest.py\", line 63, in task_fixture\n    assert create_response.status_code == 200,(\n        \"Ошибка при создании задачи\")\n"}, "steps": [{"name": "Создание задачи через API", "status": "failed", "statusDetails": {"message": "AssertionError: Ошибка при создании задачи\nassert 404 == 200\n +  where 404 = <Response [404]>.status_code\n", "trace": "  File \"/Users/iliakarpenko/Dev/test_exam/tests/conftest.py\", line 63, in task_fixture\n    assert create_response.status_code == 200,(\n        \"Ошибка при создании задачи\")\n"}, "start": 1744648566752, "stop": 1744648567056}], "start": 1744648566752, "stop": 1744648567056}], "start": 1744648566752, "stop": 1744648567066}